<?xml version="1.0" encoding="utf-8"?>
<!-- This URDF was automatically created by SolidWorks to URDF Exporter! Originally created by Stephen Brawner (brawner@gmail.com) 
     Commit Version: 1.6.0-4-g7f85cfe  Build Version: 1.6.7995.38578
     For more information, please see http://wiki.ros.org/sw_urdf_exporter -->
<robot
  name="single_arm_v22_19cm">
  <link name="dummy"/>
  <joint name="dummy_joint" type="fixed">
    <parent link="dummy"/>
    <child link="base_link"/>
    </joint>
  <link name='base_link'>
  <!-- <link
    name="base_link"> -->
    <inertial>
      <origin
        xyz="-0.00010098 -0.00035109 0.054127"
        rpy="0 0 0" />
      <mass
        value="2.94316" />
      <inertia
        ixx="0.00082016"
        ixy="3.555E-10"
        ixz="-4.1821E-06"
        iyy="0.00081979"
        iyz="-1.4527E-07"
        izz="0.00035328" />
    </inertial>
    <visual>
      <origin
        xyz="0 0 0"
        rpy="0 0 0" />
      <geometry>
        <mesh
          filename="package://single_arm_v22_19cm/meshes/base_link.STL" />
      </geometry>
      <material
        name="">
        <color
          rgba="0.89804 0.91765 0.92941 1" />
      </material>
    </visual>
    <collision>
      <origin
        xyz="0 0 0"
        rpy="0 0 0" />
      <geometry>
        <mesh
          filename="package://single_arm_v22_19cm/meshes/base_link.STL" />
      </geometry>
    </collision>
  </link>
  <link
    name="link1">
    <inertial>
      <origin
        xyz="3.305E-06 0.0036146 0.029085"
        rpy="0 0 0" />
      <mass
        value="0.93428" />
      <inertia
        ixx="0.00048112"
        ixy="-7.0827E-08"
        ixz="-3.5566E-10"
        iyy="0.00018986"
        iyz="4.1821E-06"
        izz="0.0004948" />
    </inertial>
    <visual>
      <origin
        xyz="0 0 0"
        rpy="0 0 0" />
      <geometry>
        <mesh
          filename="package://single_arm_v22_19cm/meshes/link1.STL" />
      </geometry>
      <material
        name="">
        <color
          rgba="0.89804 0.91765 0.92941 1" />
      </material>
    </visual>
    <collision>
      <origin
        xyz="0 0 0"
        rpy="0 0 0" />
      <geometry>
        <mesh
          filename="package://single_arm_v22_19cm/meshes/link1.STL" />
      </geometry>
    </collision>
  </link>
  <joint
    name="joint1"
    type="revolute">
    <origin
      xyz="0 0 0.1445"
      rpy="0 0 0" />
    <parent
      link="base_link" />
    <child
      link="link1" />
    <axis
      xyz="0 0 1" />
    <limit
      lower="-3.14"
      upper="3.14"
      effort="0"
      velocity="0" />
  </joint>
  <link
    name="link2">
    <inertial>
      <origin
        xyz="0.24012814792212073 2.033119680294266e-06 0.013246731868140259"
        rpy="0 0 0" />
      <mass
        value="0.4749073641101887"  />
      <inertia
        ixx="0.0009460509872811137"
        ixy="4.863802300098385e-08"
        ixz="-0.0007595877946933643"
        iyy="0.004009204305271554"
        iyz="-1.7174352031655893e-08"
        izz="0.0032588236518954136" />
    </inertial>
    <visual>
      <origin
        xyz="0 0 0"
        rpy="0 0 0" />
      <geometry>
        <mesh
          filename="package://dynamics/src/dynamics/meshes/single_arm_v22_19cm_2_19.0.STL" />
      </geometry>
      <material
        name="">
        <color
          rgba="0.89804 0.91765 0.92941 1" />
      </material>
    </visual>
    <collision>
      <origin
        xyz="0 0 0"
        rpy="0 0 0" />
      <geometry>
        <mesh
          filename="package://single_arm_v22_19cm/meshes/link2.STL" />
      </geometry>
    </collision>
  </link>
  <joint
    name="joint2"
    type="revolute">
    <origin
      xyz="0 -0.0685 0.0315"
      rpy="1.5708 0 0" />
    <parent
      link="link1" />
    <child
      link="link2" />
    <axis
      xyz="0 0 1" />
    <limit
      lower="-3.14"
      upper="3.14"
      effort="0"
      velocity="0" />
  </joint>
  <link
    name="link3">
    <inertial>
      <origin
        xyz="0.23114585106765023 1.6081545650122893e-07 -0.012429772770422119"
        rpy="0 0 0" />
      <mass
        value="0.4508048439271571"  />
      <inertia
        ixx="0.0007261411773385291"
        ixy="1.718782172750919e-08"
        ixz="0.0005254961214817812"
        iyy="0.0037004746498844544"
        iyz="-6.075710978199373e-10"
        izz="0.003155523429480458" />
    </inertial>
    <visual>
      <origin
        xyz="0 0 0"
        rpy="0 0 0" />
      <geometry>
        <mesh
          filename="package://dynamics/src/dynamics/meshes/single_arm_v22_19cm_3_19.0.STL" />
      </geometry>
      <material
        name="">
        <color
          rgba="0.89804 0.91765 0.92941 1" />
      </material>
    </visual>
    <collision>
      <origin
        xyz="0 0 0"
        rpy="0 0 0" />
      <geometry>
        <mesh
          filename="package://single_arm_v22_19cm/meshes/link3.STL" />
      </geometry>
    </collision>
  </link>
  <joint
    name="joint3"
    type="revolute">
    <origin
      xyz="0.304267000820369 0 -0.039"
      rpy="0 0 0" />
    <parent
      link="link2" />
    <child
      link="link3" />
    <axis
      xyz="0 0 -1" />
    <limit
      lower="-3.14"
      upper="3.14"
      effort="0"
      velocity="0" />
  </joint>
  <link
    name="link4">
    <inertial>
      <origin
        xyz="2.2204E-16 0.01039 0.02404"
        rpy="0 0 0" />
      <mass
        value="0.36924" />
      <inertia
        ixx="9.4187E-05"
        ixy="1.2869E-19"
        ixz="-1.4501E-16"
        iyy="4.476E-05"
        iyz="5.3346E-07"
        izz="0.0001027" />
    </inertial>
    <visual>
      <origin
        xyz="0 0 0"
        rpy="0 0 0" />
      <geometry>
        <mesh
          filename="package://single_arm_v22_19cm/meshes/link4.STL" />
      </geometry>
      <material
        name="">
        <color
          rgba="0.89804 0.91765 0.92941 1" />
      </material>
    </visual>
    <collision>
      <origin
        xyz="0 0 0"
        rpy="0 0 0" />
      <geometry>
        <mesh
          filename="package://single_arm_v22_19cm/meshes/link4.STL" />
      </geometry>
    </collision>
  </link>
  <joint
    name="joint4"
    type="revolute">
    <origin
      xyz="0.29573299917963103 0 0.039"
      rpy="0 0 -3.14159265358979" />
    <parent
      link="link3" />
    <child
      link="link4" />
    <axis
      xyz="0 0 1" />
    <limit
      lower="-3.14"
      upper="3.14"
      effort="0"
      velocity="0" />
  </joint>
  <link
    name="link5">
    <inertial>
      <origin
        xyz="0.028614 0.010457 -3.3307E-16"
        rpy="0 0 0" />
      <mass
        value="0.36821" />
      <inertia
        ixx="0.00010133"
        ixy="5.3346E-07"
        ixz="1.4501E-16"
        iyy="4.3878E-05"
        iyz="-8.1817E-20"
        izz="9.3658E-05" />
    </inertial>
    <visual>
      <origin
        xyz="0 0 0"
        rpy="0 0 0" />
      <geometry>
        <mesh
          filename="package://single_arm_v22_19cm/meshes/link5.STL" />
      </geometry>
      <material
        name="">
        <color
          rgba="0.89804 0.91765 0.92941 1" />
      </material>
    </visual>
    <collision>
      <origin
        xyz="0 0 0"
        rpy="0 0 0" />
      <geometry>
        <mesh
          filename="package://single_arm_v22_19cm/meshes/link5.STL" />
      </geometry>
    </collision>
  </link>
  <joint
    name="joint5"
    type="revolute">
    <origin
      xyz="0 0.052 0.0286"
      rpy="1.5707963267949 0 1.5707963267949" />
    <parent
      link="link4" />
    <child
      link="link5" />
    <axis
      xyz="1 0 0" />
    <limit
      lower="-3.14"
      upper="3.14"
      effort="0"
      velocity="0" />
  </joint>
  <link
    name="link6">
    <inertial>
      <origin
        xyz="-4.44089209850063E-16 5.37938091366846E-07 -0.00700006055550936"
        rpy="0 0 0" />
      <mass
        value="0.0259770442543706" />
      <inertia
        ixx="2.20534281951167E-06"
        ixy="1.78671012311437E-22"
        ixz="-8.79317315621994E-22"
        iyy="2.20534281951168E-06"
        iyz="2.32583060538047E-20"
        izz="3.9777349014505E-06" />
    </inertial>
    <visual>
      <origin
        xyz="0 0 0"
        rpy="0 0 0" />
      <geometry>
        <mesh
          filename="package://single_arm_v22_19cm/meshes/link6.STL" />
      </geometry>
      <material
        name="">
        <color
          rgba="0.898039215686275 0.917647058823529 0.929411764705882 1" />
      </material>
    </visual>
    <collision>
      <origin
        xyz="0 0 0"
        rpy="0 0 0" />
      <geometry>
        <mesh
          filename="package://single_arm_v22_19cm/meshes/link6.STL" />
      </geometry>
    </collision>
  </link>
  <joint
    name="joint6"
    type="revolute">
    <origin
      xyz="0.0330005379381037 0.0549999394444907 0"
      rpy="1.57079632679488 -1.5707963267949 0" />
    <parent
      link="link5" />
    <child
      link="link6" />
    <axis
      xyz="0 0 1" />
    <limit
      lower="-3.14"
      upper="3.14"
      effort="0"
      velocity="0" />
  </joint>
</robot>