<?xml version="1.0"?>
<robot name="single_arm_v11" xmlns:xacro="http://www.ros.org/wiki/xacro">

  <xacro:include filename="$(find single_arm_v11)/single_arm_v11_description/urdf/single_arm_v11.transmission.xacro"/>
  <xacro:include filename="$(find single_arm_v11)/single_arm_v11_description/urdf/single_arm_v11.gazebo.xacro"/>
  <!-- <xacro:include filename="$(find single_arm_v11)/single_arm_v11_description/urdf/materials.xacro"/> -->
  
  <!-- Constants for robot dimensions -->
	<!-- <xacro:macro name="single_arm_v11_xacro" params="parent *origin"> -->

    <link name="world"/>
	<joint name="world_base" type="fixed">
		<parent link="world"/>
		<child link="base_link"/>
		<origin xyz="0 0 0.01" rpy="0 0 0" />
	</joint>

	<link name="base_link">
		<inertial>
			<origin
				xyz="-0.00015625 -0.00020296 0.054397"
				rpy="0 0 0" />
			<mass
				value="0.47711" />
			<inertia
				ixx="0.00059036"
				ixy="3.555E-10"
				ixz="-4.1821E-06"
				iyy="0.00058997"
				iyz="-9.8398E-08"
				izz="0.00022102" />
		</inertial>
		<visual>
			<origin
				xyz="0 0 0"
				rpy="0 0 0" />
			<geometry>
				<mesh filename="package://single_arm_v11/single_arm_v11_description/meshes/base_link.STL" />
			</geometry>
			<material
				name="">
				<color rgba="0.79216 0.81961 0.93333 1" />
			</material>
		</visual>
		<collision>
			<origin
				xyz="0 0 0"
				rpy="0 0 0" />			
			<geometry>
				<mesh filename="package://single_arm_v11/single_arm_v11_description/meshes/base_link.STL" />
			</geometry>
		</collision>
	</link>
 
	<link name="Link1">
		<inertial>
			<origin
				xyz="3.4484E-06 -0.00039863 -0.028769"
				rpy="0 0 0" />
			<mass
				value="0.38613" />
			<inertia
				ixx="0.00047431"
				ixy="7.0827E-08"
				ixz="3.5556E-10"
				iyy="0.00017465"
				iyz="4.1821E-06"
				izz="0.00048907" />
		</inertial>
		<visual>
			<origin
				xyz="0 0 0"
				rpy="0 0 0" />
			<geometry>
				<mesh filename="package://single_arm_v11/single_arm_v11_description/meshes/Link1.STL" />
			</geometry>
			<material
				name="">
				<color rgba="0.89804 0.91765 0.92941 1" />
			</material>
		</visual>
		<collision>
			<origin
				xyz="0 0 0"
				rpy="0 0 0" />
			<geometry>
				<mesh filename="package://single_arm_v11/single_arm_v11_description/meshes/Link1.STL" />
			</geometry>
		</collision>
	</link>
	<joint name="Joint1" type="revolute">
		<origin
			xyz="0 0 0.1345"
			rpy="-3.1416 0 -1.5708" />
		<parent 
			link="base_link" />
		<child
			link="Link1" />
		<axis
			xyz="0 0 -1" />
		<limit
			lower="-3.14"
			upper="3.14"
			effort="1000"
			velocity="6.5" />
		<dynamics damping="0.7"/>
	</joint>
	<link
		name="Link2">
		<inertial>
		<origin
			xyz="0.13947 0.00058219 -0.0074566"
			rpy="0 0 0" />
		<mass
			value="0.58825" />
		<inertia
			ixx="0.00057122"
			ixy="-1.1203E-06"
			ixz="-3.5733E-06"
			iyy="0.0006232"
			iyz="-8.2912E-08"
			izz="0.00038379" />
		</inertial>
		<visual>
		<origin
			xyz="0 0 0"
			rpy="0 0 0" />
		<geometry>
			<mesh
			filename="package://single_arm_v11/single_arm_v11_description/meshes/Link2.STL" />
		</geometry>
		<material
			name="">
			<color
			rgba="0.89804 0.91765 0.92941 1" />
		</material>
		</visual>
		<collision>
		<origin
			xyz="0 0 0"
			rpy="0 0 0" />
		<geometry>
			<mesh
			filename="package://single_arm_v11/single_arm_v11_description/meshes/Link2.STL" />
		</geometry>
		</collision>
	</link>
	  <joint
			name="Joint2"
			type="revolute">
		<origin
			xyz="0 0.0695 -0.0315"
			rpy="1.5708 1.5708 0" />
		<parent
			link="Link1" />
		<child
			link="Link2" />
		<axis
			xyz="0 0 1" />
		<limit
			lower="-3.14"
			upper="3.14"
			effort="1000"
			velocity="6.5" />
		<dynamics damping="0.7"/>
	  </joint>
	  <link
		name="Link3">
		<inertial>
		<origin
			xyz="0.13622 -0.00047472 0.0063718"
			rpy="0 0 0" />
		<mass
			value="0.55444" />
		<inertia
			ixx="0.00052289"
			ixy="8.7953E-07"
			ixz="3.5629E-06"
			iyy="0.00057711"
			iyz="-8.2898E-08"
			izz="0.00036757" />
		</inertial>
		<visual>
		  <origin
		xyz="0 0 0"
		rpy="0 0 0" />
		<geometry>
			<mesh
			filename="package://single_arm_v11/single_arm_v11_description/meshes/Link3.STL" />
		</geometry>
		<material
			name="">
			<color
			rgba="0.89804 0.91765 0.92941 1" />
		</material>
		</visual>
		<collision>
		<origin
			xyz="0 0 0"
			rpy="0 0 0" />
		<geometry>
			<mesh
			filename="package://single_arm_v11/single_arm_v11_description/meshes/Link3.STL" />
		</geometry>
		</collision>
	  </link>
	  <joint
			name="Joint3"
			type="revolute">
		<origin
			xyz="0.214 0 0.0345"
			rpy="0 0 0" />
		<parent
			link="Link2" />
		<child
			link="Link3" />
		<axis
			xyz="0 0 -1" />
		<limit
			lower="-3.14"
			upper="3.14"
			effort="1000"
			velocity="6.5" />
		<dynamics damping="0.7"/>
	  </joint>
	  <link
		name="Link4">
		<inertial>
		<origin
			xyz="4.83814377449931E-15 0.0124471610012715 -0.0319494763505741"
			rpy="0 0 0" />
		<mass
			value="0.313854171959485" />
		<inertia
			ixx="0.00030905374217572"
			ixy="1.62700962442E-20"
			ixz="2.09983644469817E-19"
			iyy="0.000138417182248756"
			iyz="3.51429818496665E-06"
			izz="0.000324741574348904" />
		</inertial>
		<visual>
		<origin
			xyz="0 0 0"
			rpy="0 0 0" />
		<geometry>
			<mesh
			filename="package://single_arm_v11/single_arm_v11_description/meshes/Link4.STL" />
		</geometry>
		<material
			name="">
			<color
			rgba="0.898039215686275 0.917647058823529 0.929411764705882 1" />
		</material>
		</visual>
		<collision>
		<origin
			xyz="0 0 0"
			rpy="0 0 0" />
		<geometry>
			<mesh
			filename="package://single_arm_v11/single_arm_v11_description/meshes/Link4.STL" />
		</geometry>
		</collision>
	  </link>
	  <joint
			name="Joint4"
			type="revolute">
		<origin
			xyz="0.214 0 -0.0321"
			rpy="0 0 -1.5708" />
		<parent
			link="Link3" />
		<child
			link="Link4" />
		<axis
			xyz="0 0 1" />
		<limit
			lower="-3.14"
			upper="3.14"
			effort="1000"
			velocity="6.5" />
		<dynamics damping="0.7"/>
	  </joint>
	  <link
			name="Link5">
		<inertial>
		<origin
			xyz="-8.71178129635553E-15 0.0124471610012712 -0.0319494763505744"
			rpy="0 0 0" />
		<mass
			value="0.313854171959485" />
		<inertia
			ixx="0.00030905374217572"
			ixy="2.20240357597189E-20"
			ixz="1.70643067941476E-20"
			iyy="0.000138417182248756"
			iyz="3.51429818496703E-06"
			izz="0.000324741574348904" />
		</inertial>
		<visual>
		<origin
			xyz="0 0 0"
			rpy="0 0 0" />
		<geometry>
			<mesh
			filename="package://single_arm_v11/single_arm_v11_description/meshes/Link5.STL" />
		</geometry>
		<material
			name="">
			<color
			rgba="0.898039215686275 0.917647058823529 0.929411764705882 1" />
		</material>
		</visual>
		<collision>
		<origin
			xyz="0 0 0"
			rpy="0 0 0" />
		<geometry>
			<mesh
			filename="package://single_arm_v11/single_arm_v11_description/meshes/Link5.STL" />
		</geometry>
		</collision>
	  </link>
	  <joint
			name="Joint5"
			type="revolute">
		<origin
			xyz="0 0.0671 -0.036"
			rpy="-1.5708 0 -3.1416" />
		<parent
			link="Link4" />
		<child
			link="Link5" />
		<axis
			xyz="0 0 1" />
		<limit
			lower="-3.14"
			upper="3.14"
			effort="1000"
			velocity="6.5" />
		<dynamics damping="0.7"/>
	  </joint>
	  <link
		name="Link6">
		<inertial>
		<origin
			xyz="3.28966953833032E-05 -0.311761303173634 -0.12146386078719"
			rpy="0 0 0" />
		<mass
			value="5.52667031461374" />
		<inertia
			ixx="0.325455467014091"
			ixy="0.000107387844284919"
			ixz="4.23563408960176E-05"
			iyy="0.0196746763653344"
			iyz="-0.0445528342714575"
			izz="0.308584695412345" />
		</inertial>
		<visual>
		<origin
			xyz="0 0 0"
			rpy="0 0 0" />
		<geometry>
			<mesh
			filename="package://single_arm_v11/single_arm_v11_description/meshes/Link6.STL" />
		</geometry>
		<material
			name="">
			<color
			rgba="1 1 1 1" />
		</material>
		</visual>
		<collision>
		<origin
			xyz="0 0 0"
			rpy="0 0 0" />
		<geometry>
			<mesh
			filename="package://single_arm_v11/single_arm_v11_description/meshes/Link6.STL" />
		</geometry>
		</collision>
	  </link>
	  <joint
			name="Joint6"
			type="revolute">
		<origin
			xyz="0 0.069 -0.036"
			rpy="-1.5708 0 0" />
		<parent
			link="Link5" />
		<child
			link="Link6" />
		<axis
			xyz="0 0 1" />
		<limit
			lower="-3.14"
			upper="3.14"
			effort="1000"
			velocity="6.5" />
		<dynamics damping="0.7"/>
	  </joint>
	  
	  <xacro:single_arm_v11_transmission />
	  <xacro:single_arm_v11_gazebo />
	<!-- </xacro:macro> -->
</robot>