<?xml version="1.0" encoding="utf-8"?>
<!-- This URDF was automatically created by SolidWorks to URDF Exporter! Originally created by Stephen Brawner (brawner@gmail.com) 
     Commit Version: 1.6.0-4-g7f85cfe  Build Version: 1.6.7995.38578
     For more information, please see http://wiki.ros.org/sw_urdf_exporter -->
<robot
  name="single_arm_v12">
  <link
    name="base_link">
    <inertial>
      <origin
        xyz="0.000156250860732343 0.000202963757501833 0.0643974948398569"
        rpy="0 0 0" />
      <mass
        value="0.477111748769872" />
      <inertia
        ixx="0.000590360417130005"
        ixy="3.55501513767024E-10"
        ixz="4.18207256662998E-06"
        iyy="0.000589971083789895"
        iyz="9.83975740648705E-08"
        izz="0.000221020393022398" />
    </inertial>
    <visual>
      <origin
        xyz="0 0 0"
        rpy="0 0 0" />
      <geometry>
        <mesh
          filename="package://single_arm_v12/meshes/base_link.STL" />
      </geometry>
      <material
        name="">
        <color
          rgba="0.792156862745098 0.819607843137255 0.933333333333333 1" />
      </material>
    </visual>
    <collision>
      <origin
        xyz="0 0 0"
        rpy="0 0 0" />
      <geometry>
        <mesh
          filename="package://single_arm_v12/meshes/base_link.STL" />
      </geometry>
    </collision>
  </link>
  <link
    name="Link1">
    <inertial>
      <origin
        xyz="3.44839622268278E-06 0.000398625697735053 0.0287689793053224"
        rpy="0 0 0" />
      <mass
        value="0.386131223153925" />
      <inertia
        ixx="0.00047431002724688"
        ixy="-7.08270540818844E-08"
        ixz="-3.55559180801277E-10"
        iyy="0.00017465191552395"
        iyz="4.18207766639286E-06"
        izz="0.000489072616009742" />
    </inertial>
    <visual>
      <origin
        xyz="0 0 0"
        rpy="0 0 0" />
      <geometry>
        <mesh
          filename="package://single_arm_v12/meshes/Link1.STL" />
      </geometry>
      <material
        name="">
        <color
          rgba="0.792156862745098 0.819607843137255 0.933333333333333 1" />
      </material>
    </visual>
    <collision>
      <origin
        xyz="0 0 0"
        rpy="0 0 0" />
      <geometry>
        <mesh
          filename="package://single_arm_v12/meshes/Link1.STL" />
      </geometry>
    </collision>
  </link>
  <joint
    name="Joint1"
    type="revolute">
    <origin
      xyz="0 0 0.1445"
      rpy="0 0 0" />
    <parent
      link="base_link" />
    <child
      link="Link1" />
    <axis
      xyz="0 0 1" />
    <limit
      lower="-3.14"
      upper="3.14"
      effort="0"
      velocity="0" />
  </joint>
  <link
    name="Link2">
    <inertial>
      <origin
        xyz="0.29289 -0.0006317 0.0089324"
        rpy="0 0 0" />
      <mass
        value="0.68686" />
      <inertia
        ixx="0.00061348"
        ixy="1.0756E-06"
        ixz="3.5701E-06"
        iyy="0.0020676"
        iyz="-8.2912E-08"
        izz="0.0018139" />
    </inertial>
    <visual>
      <origin
        xyz="0 0 0"
        rpy="0 0 0" />
      <geometry>
        <mesh
          filename="package://single_arm_v12/meshes/Link2.STL" />
      </geometry>
      <material
        name="">
        <color
          rgba="0.89804 0.91765 0.92941 1" />
      </material>
    </visual>
    <collision>
      <origin
        xyz="0 0 0"
        rpy="0 0 0" />
      <geometry>
        <mesh
          filename="package://single_arm_v12/meshes/Link2.STL" />
      </geometry>
    </collision>
  </link>
  <joint
    name="Joint2"
    type="revolute">
    <origin
      xyz="0 -0.0685 0.0315"
      rpy="1.5708 0 0" />
    <parent
      link="Link1" />
    <child
      link="Link2" />
    <axis
      xyz="0 0 1" />
    <limit
      lower="-3.14"
      upper="3.14"
      effort="0"
      velocity="0" />
  </joint>
  <link
    name="Link3">
    <inertial>
      <origin
        xyz="0.293727343440639 0.000417642376989547 -0.0108146077958978"
        rpy="0 0 0" />
      <mass
        value="0.630198008343518" />
      <inertia
        ixx="0.000546352619320372"
        ixy="-8.79478913093369E-07"
        ixz="-3.57003725526669E-06"
        iyy="0.00200340317687267"
        iyz="-8.29116899083369E-08"
        izz="0.00179626888676536" />
    </inertial>
    <visual>
      <origin
        xyz="0 0 0"
        rpy="0 0 0" />
      <geometry>
        <mesh
          filename="package://single_arm_v12/meshes/Link3.STL" />
      </geometry>
      <material
        name="">
        <color
          rgba="0.898039215686275 0.917647058823529 0.929411764705882 1" />
      </material>
    </visual>
    <collision>
      <origin
        xyz="0 0 0"
        rpy="0 0 0" />
      <geometry>
        <mesh
          filename="package://single_arm_v12/meshes/Link3.STL" />
      </geometry>
    </collision>
  </link>
  <joint
    name="Joint3"
    type="revolute">
    <origin
      xyz="0.494 0 -0.0325"
      rpy="0 0 0" />
    <parent
      link="Link2" />
    <child
      link="Link3" />
    <axis
      xyz="0 0 -1" />
    <limit
      lower="-3.14"
      upper="3.14"
      effort="0"
      velocity="0" />
  </joint>
  <link
    name="Link4">
    <inertial>
      <origin
        xyz="-2.2204E-16 0.012447 0.030549"
        rpy="0 0 0" />
      <mass
        value="0.31385" />
      <inertia
        ixx="0.00030905"
        ixy="1.4473E-19"
        ixz="-1.3366E-20"
        iyy="0.00013842"
        iyz="-3.5143E-06"
        izz="0.00032474" />
    </inertial>
    <visual>
      <origin
        xyz="0 0 0"
        rpy="0 0 0" />
      <geometry>
        <mesh
          filename="package://single_arm_v12/meshes/Link4.STL" />
      </geometry>
      <material
        name="">
        <color
          rgba="0.89804 0.91765 0.92941 1" />
      </material>
    </visual>
    <collision>
      <origin
        xyz="0 0 0"
        rpy="0 0 0" />
      <geometry>
        <mesh
          filename="package://single_arm_v12/meshes/Link4.STL" />
      </geometry>
    </collision>
  </link>
  <joint
    name="Joint4"
    type="revolute">
    <origin
      xyz="0.494 0 0.0325"
      rpy="0 0 3.1416" />
    <parent
      link="Link3" />
    <child
      link="Link4" />
    <axis
      xyz="0 0 1" />
    <limit
      lower="-3.14"
      upper="3.14"
      effort="0"
      velocity="0" />
  </joint>
  <link
    name="Link5">
    <inertial>
      <origin
        xyz="0.0305494763505954 0.0124160882702145 -0.000878959076247465"
        rpy="0 0 0" />
      <mass
        value="0.313854171959487" />
      <inertia
        ixx="0.000324741574348904"
        ixy="-3.50552519309464E-06"
        ixz="2.48162957481342E-07"
        iyy="0.000139268063164469"
        iyz="1.201945897418E-05"
        izz="0.000308202861260007" />
    </inertial>
    <visual>
      <origin
        xyz="0 0 0"
        rpy="0 0 0" />
      <geometry>
        <mesh
          filename="package://single_arm_v12/meshes/Link5.STL" />
      </geometry>
      <material
        name="">
        <color
          rgba="0.898039215686275 0.917647058823529 0.929411764705882 1" />
      </material>
    </visual>
    <collision>
      <origin
        xyz="0 0 0"
        rpy="0 0 0" />
      <geometry>
        <mesh
          filename="package://single_arm_v12/meshes/Link5.STL" />
      </geometry>
    </collision>
  </link>
  <joint
    name="Joint5"
    type="revolute">
    <origin
      xyz="0 0.0684999999999999 0.0346"
      rpy="1.5707963267949 0 1.5707963267949" />
    <parent
      link="Link4" />
    <child
      link="Link5" />
    <axis
      xyz="-1 0 0" />
    <limit
      lower="-3.14"
      upper="3.14"
      effort="0"
      velocity="0" />
  </joint>
  <link
    name="Link6">
    <inertial>
      <origin
        xyz="-0.474282148873093 0.068873611593725 -0.154887984610123"
        rpy="0 0 0" />
      <mass
        value="5.70103597964746" />
      <inertia
        ixx="0.0503204120573967"
        ixy="-0.0117928110271336"
        ixz="-0.151490044346827"
        iyy="1.11950099408196"
        iyz="-0.000515936470304746"
        izz="1.09998620966789" />
    </inertial>
    <visual>
      <origin
        xyz="0 0 0"
        rpy="0 0 0" />
      <geometry>
        <mesh
          filename="package://single_arm_v12/meshes/Link6.STL" />
      </geometry>
      <material
        name="">
        <color
          rgba="1 1 1 1" />
      </material>
    </visual>
    <collision>
      <origin
        xyz="0 0 0"
        rpy="0 0 0" />
      <geometry>
        <mesh
          filename="package://single_arm_v12/meshes/Link6.STL" />
      </geometry>
    </collision>
  </link>
  <joint
    name="Joint6"
    type="revolute">
    <origin
      xyz="0.0346000000000223 0.0683289985903639 -0.00483714292092552"
      rpy="3.14159265358912 1.50012228233503 -1.57079632679559" />
    <parent
      link="Link5" />
    <child
      link="Link6" />
    <axis
      xyz="0 0 1" />
    <limit
      lower="-3.14"
      upper="3.14"
      effort="0"
      velocity="0" />
  </joint>
</robot>