<?xml version="1.0" encoding="utf-8"?>
<!-- This URDF was automatically created by SolidWorks to URDF Exporter! Originally created by Stephen Brawner (brawner@gmail.com) 
     Commit Version: 1.6.0-4-g7f85cfe  Build Version: 1.6.7995.38578
     For more information, please see http://wiki.ros.org/sw_urdf_exporter -->
<robot
  name="single_arm_v12">
  <link name="dummy"/>
  <joint name="dummy_joint" type="fixed">
    <parent link="dummy"/>
    <child link="base_link"/>
    </joint>
  <link name='base_link'>
  <!-- <link
    name="base_link"> -->
    <inertial>
      <origin
        xyz="0.00015625 0.00020296 0.064397"
        rpy="0 0 0" />
      <mass
        value="0.47711" />
      <inertia
        ixx="0.00059036"
        ixy="3.555E-10"
        ixz="4.1821E-06"
        iyy="0.00058997"
        iyz="9.8398E-08"
        izz="0.00022102" />
    </inertial>
    <visual>
      <origin
        xyz="0 0 0"
        rpy="0 0 0" />
      <geometry>
        <mesh
          filename="package://single_arm_v12/meshes/base_link.STL" />
      </geometry>
      <material
        name="">
        <color
          rgba="0.79216 0.81961 0.93333 1" />
      </material>
    </visual>
    <collision>
      <origin
        xyz="0 0 0"
        rpy="0 0 0" />
      <geometry>
        <mesh
          filename="package://single_arm_v12/meshes/base_link.STL" />
      </geometry>
    </collision>
  </link>
  <link
    name="Link1">
    <inertial>
      <origin
        xyz="3.4484E-06 0.00039863 0.028769"
        rpy="0 0 0" />
      <mass
        value="0.38613" />
      <inertia
        ixx="0.00047431"
        ixy="-7.0827E-08"
        ixz="-3.5556E-10"
        iyy="0.00017465"
        iyz="4.1821E-06"
        izz="0.00048907" />
    </inertial>
    <visual>
      <origin
        xyz="0 0 0"
        rpy="0 0 0" />
      <geometry>
        <mesh
          filename="package://single_arm_v12/meshes/Link1.STL" />
      </geometry>
      <material
        name="">
        <color
          rgba="0.79216 0.81961 0.93333 1" />
      </material>
    </visual>
    <collision>
      <origin
        xyz="0 0 0"
        rpy="0 0 0" />
      <geometry>
        <mesh
          filename="package://single_arm_v12/meshes/Link1.STL" />
      </geometry>
    </collision>
  </link>
  <joint
    name="Joint1"
    type="revolute">
    <origin
      xyz="0 0 0.1445"
      rpy="0 0 0" />
    <parent
      link="base_link" />
    <child
      link="Link1" />
    <axis
      xyz="0 0 1" />
    <limit
      lower="-3.14"
      upper="3.14"
      effort="50"
      velocity="0" />
  </joint>
  <link
    name="Link2">
    <inertial>
      <origin
<<<<<<< HEAD
        xyz="0.3206861445726523 -0.00031958204578206906 0.019300226267368385"
        rpy="0 0 0" />
      <mass
        value="0.49099218860259525"  />
      <inertia
        ixx="0.0011226963151510084"
        ixy="-4.308180445936682e-05"
        ixz="-0.0013617652689265427"
        iyy="0.007953242827353345"
        iyz="-1.562115932592594e-05"
        izz="0.007063415787080681" />
=======
        xyz="0.38693170370115737 -0.0002998158936552522 0.020332151021099077"
        rpy="0 0 0" />
      <mass
        value="0.5138042752232314"  />
      <inertia
        ixx="0.0011372959566660747"
        ixy="-5.372102965196798e-05"
        ixz="-0.0016838248343437581"
        iyy="0.009911642123134504"
        iyz="-1.5789001340153304e-05"
        izz="0.009013203868740665" />
>>>>>>> mac_test
    </inertial>
    <visual>
      <origin
        xyz="0 0 0"
        rpy="0 0 0" />
      <geometry>
        <mesh
          filename="package://dynamics/src/dynamics/meshes/merged_single_arm_axis_2.STL" />
      </geometry>
      <material
        name="">
        <color
          rgba="0.89804 0.91765 0.92941 1" />
      </material>
    </visual>
    <collision>
      <origin
        xyz="0 0 0"
        rpy="0 0 0" />
      <geometry>
        <mesh
          filename="package://dynamics/src/dynamics/meshes/merged_single_arm_axis_2.STL" />
      </geometry>
    </collision>
  </link>
  <joint
    name="Joint2"
    type="revolute">
    <origin
      xyz="0 -0.0685 0.0315"
      rpy="1.5708 0 0" />
    <parent
      link="Link1" />
    <child
      link="Link2" />
    <axis
      xyz="0 0 1" />
    <limit
      lower="-3.14"
      upper="3.14"
      effort="50"
      velocity="0" />
  </joint>
  <link
    name="Link3">
    <inertial>
      <origin
<<<<<<< HEAD
        xyz="0.28668155494202197 0.000221262817961842 -0.01765935386055889"
        rpy="0 0 0" />
      <mass
        value="0.43995216890701616"  />
      <inertia
        ixx="0.0007999082948228022"
        ixy="2.3407846657384797e-05"
        ixz="0.0007329680304742151"
        iyy="0.006168438808384789"
        iyz="-8.904726054831544e-06"
        izz="0.0055805227141689385" />
=======
        xyz="0.36325368081650655 0.0002051400968318283 -0.019078471025675062"
        rpy="0 0 0" />
      <mass
        value="0.46633726625192845"  />
      <inertia
        ixx="0.0008184439024192132"
        ixy="3.096392332507958e-05"
        ixz="0.0009562848065829495"
        iyy="0.008244030581126242"
        iyz="-9.032059300049537e-06"
        izz="0.007644497680351588" />
>>>>>>> mac_test
    </inertial>
    <visual>
      <origin
        xyz="0 0 0"
        rpy="0 0 0" />
      <geometry>
        <mesh
          filename="package://dynamics/src/dynamics/meshes/merged_single_arm_axis_3.STL" />
      </geometry>
      <material
        name="">
        <color
          rgba="0.898039215686275 0.917647058823529 0.929411764705882 1" />
      </material>
    </visual>
    <collision>
      <origin
        xyz="0 0 0"
        rpy="0 0 0" />
      <geometry>
        <mesh
          filename="package://dynamics/src/dynamics/meshes/merged_single_arm_axis_3.STL" />
      </geometry>
    </collision>
  </link>
  <joint
    name="Joint3"
    type="revolute">
    <origin
<<<<<<< HEAD
      xyz="0.4197760358145669 0 -0.0325"
=======
      xyz="0.5096499999999999 0 -0.0325"
>>>>>>> mac_test
      rpy="0 0 0" />
    <parent
      link="Link2" />
    <child
      link="Link3" />
    <axis
      xyz="0 0 -1" />
    <limit
      lower="-3.14"
      upper="3.14"
      effort="50"
      velocity="0" />
  </joint>
  <link
    name="Link4">
    <inertial>
      <origin
        xyz="-1.11022302462516E-16 0.0124471610012716 0.0305494763505743"
        rpy="0 0 0" />
      <mass
        value="0.313854171959486" />
      <inertia
        ixx="0.00030905374217572"
        ixy="2.20104937481116E-19"
        ixz="1.99389141092033E-20"
        iyy="0.000138417182248756"
        iyz="-3.51429818496687E-06"
        izz="0.000324741574348905" />
    </inertial>
    <visual>
      <origin
        xyz="0 0 0"
        rpy="0 0 0" />
      <geometry>
        <mesh
          filename="package://single_arm_v12/meshes/Link4.STL" />
      </geometry>
      <material
        name="">
        <color
          rgba="0.898039215686275 0.917647058823529 0.929411764705882 1" />
      </material>
    </visual>
    <collision>
      <origin
        xyz="0 0 0"
        rpy="0 0 0" />
      <geometry>
        <mesh
          filename="package://single_arm_v12/meshes/Link4.STL" />
      </geometry>
    </collision>
  </link>
  <joint
    name="Joint4"
    type="revolute">
    <origin
<<<<<<< HEAD
      xyz="0.3743992697216084 0 0.0325"
=======
      xyz="0.47835000000000005 0 0.0325"
>>>>>>> mac_test
      rpy="0 0 3.1416" />
    <parent
      link="Link3" />
    <child
      link="Link4" />
    <axis
      xyz="0 0 1" />
    <limit
      lower="-3.14"
      upper="3.14"
      effort="50"
      velocity="0" />
  </joint>
  <link
    name="Link5">
    <inertial>
      <origin
        xyz="0.0305494763505902 0.0124160882702156 -0.000878959076247798"
        rpy="0 0 0" />
      <mass
        value="0.313854171959487" />
      <inertia
        ixx="0.000324741574348905"
        ixy="-3.50552519309465E-06"
        ixz="2.48162957481373E-07"
        iyy="0.000139268063164469"
        iyz="1.20194589741801E-05"
        izz="0.000308202861260008" />
    </inertial>
    <visual>
      <origin
        xyz="0 0 0"
        rpy="0 0 0" />
      <geometry>
        <mesh
          filename="package://single_arm_v12/meshes/Link5.STL" />
      </geometry>
      <material
        name="">
        <color
          rgba="0.898039215686275 0.917647058823529 0.929411764705882 1" />
      </material>
    </visual>
    <collision>
      <origin
        xyz="0 0 0"
        rpy="0 0 0" />
      <geometry>
        <mesh
          filename="package://single_arm_v12/meshes/Link5.STL" />
      </geometry>
    </collision>
  </link>
  <joint
    name="Joint5"
    type="revolute">
    <origin
      xyz="0 0.0685 0.0346"
      rpy="1.5708 0 1.5708" />
    <parent
      link="Link4" />
    <child
      link="Link5" />
    <axis
      xyz="-1 0 0" />
    <limit
      lower="-3.14"
      upper="3.14"
      effort="50"
      velocity="0" />
  </joint>
  <link
    name="Link6">
    <inertial>
      <origin
        xyz="-1.11022302462516E-16 1.73472347597681E-18 0.0055"
        rpy="0 0 0" />
      <mass
        value="0.0173494454294496" />
      <inertia
        ixx="2.53988652151547E-06"
        ixy="-2.00729161979554E-22"
        ixz="-3.90838944351189E-22"
        iyy="2.53988652151547E-06"
        iyz="-1.17534537510526E-22"
        izz="4.79061561920678E-06" />
    </inertial>
    <visual>
      <origin
        xyz="0 0 0"
        rpy="0 0 0" />
      <geometry>
        <mesh
          filename="package://single_arm_v12/meshes/Link6.STL" />
      </geometry>
      <material
        name="">
        <color
          rgba="1 1 1 1" />
      </material>
    </visual>
    <collision>
      <origin
        xyz="0 0 0"
        rpy="0 0 0" />
      <geometry>
        <mesh
          filename="package://single_arm_v12/meshes/Link6.STL" />
      </geometry>
    </collision>
  </link>
  <joint
    name="Joint6"
    type="revolute">
    <origin
      xyz="0.0346 0.0685 0"
      rpy="1.5708 -1.5708 0" />
    <parent
      link="Link5" />
    <child
      link="Link6" />
    <axis
      xyz="0 0 1" />
    <limit
      lower="-3.14"
      upper="3.14"
      effort="50"
      velocity="0" />
  </joint>
</robot>