<?xml version="1.0" encoding="utf-8"?>
<!-- This URDF was automatically created by SolidWorks to URDF Exporter! Originally created by Stephen Brawner (brawner@gmail.com) 
     Commit Version: 1.6.0-4-g7f85cfe  Build Version: 1.6.7995.38578
     For more information, please see http://wiki.ros.org/sw_urdf_exporter -->
<robot
  name="single_arm_v12">
   <link name="dummy"/>
  <joint name="dummy_joint" type="fixed">
    <parent link="dummy"/>
    <child link="base_link"/>
    </joint>
  <link name='base_link'>
  <!-- <link
    name="base_link"> -->
    <inertial>
      <origin
        xyz="0.00015625 0.00020296 0.064397"
        rpy="0 0 0" />
      <mass
        value="0.47711" />
      <inertia
        ixx="0.00059036"
        ixy="3.555E-10"
        ixz="4.1821E-06"
        iyy="0.00058997"
        iyz="9.8398E-08"
        izz="0.00022102" />
    </inertial>
    <visual>
      <origin
        xyz="0 0 0"
        rpy="0 0 0" />
      <geometry>
        <mesh
          filename="package://single_arm_v12/meshes/base_link.STL" />
      </geometry>
      <material
        name="">
        <color
          rgba="0.79216 0.81961 0.93333 1" />
      </material>
    </visual>
    <collision>
      <origin
        xyz="0 0 0"
        rpy="0 0 0" />
      <geometry>
        <mesh
          filename="package://single_arm_v12/meshes/base_link.STL" />
      </geometry>
    </collision>
  </link>
  <link
    name="Link1">
    <inertial>
      <origin
        xyz="3.4484E-06 0.00039863 0.028769"
        rpy="0 0 0" />
      <mass
        value="0.38613" />
      <inertia
        ixx="0.00047431"
        ixy="-7.0827E-08"
        ixz="-3.5556E-10"
        iyy="0.00017465"
        iyz="4.1821E-06"
        izz="0.00048907" />
    </inertial>
    <visual>
      <origin
        xyz="0 0 0"
        rpy="0 0 0" />
      <geometry>
        <mesh
          filename="package://single_arm_v12/meshes/Link1.STL" />
      </geometry>
      <material
        name="">
        <color
          rgba="0.79216 0.81961 0.93333 1" />
      </material>
    </visual>
    <collision>
      <origin
        xyz="0 0 0"
        rpy="0 0 0" />
      <geometry>
        <mesh
          filename="package://single_arm_v12/meshes/Link1.STL" />
      </geometry>
    </collision>
  </link>
  <joint
    name="Joint1"
    type="revolute">
    <origin
      xyz="0 0 0.1445"
      rpy="0 0 0" />
    <parent
      link="base_link" />
    <child
      link="Link1" />
    <axis
      xyz="0 0 1" />
    <limit
      lower="-3.14"
      upper="3.14"
      effort="0"
      velocity="0" />
  </joint>
  <link
    name="Link2">
    <inertial>
      <origin
        xyz="0.1993765140209572 -0.0003557780511215574 0.017410553777935746"
        rpy="0 0 0" />
      <mass
        value="0.44921843295062003"  />
      <inertia
        ixx="0.0010959612835250508"
        ixy="-2.359913279880896e-05"
        ixz="-0.0007720060849091669"
        iyy="0.004366999490149984"
        iyz="-1.531380509713186e-05"
        izz="0.0034929414043156867" />
    </inertial>
    <visual>
      <origin
        xyz="0 0 0"
        rpy="0 0 0" />
      <geometry>
        <mesh
          filename="package://dynamics/src/dynamics/meshes/single_arm_v12_2_12.0.STL" />
      </geometry>
      <material
        name="">
        <color
          rgba="0.89804 0.91765 0.92941 1" />
      </material>
    </visual>
    <collision>
      <origin
        xyz="0 0 0"
        rpy="0 0 0" />
      <geometry>
        <mesh
          filename="package://single_arm_v12/meshes/Link2.STL" />
      </geometry>
    </collision>
  </link>
  <joint
    name="Joint2"
    type="revolute">
    <origin
      xyz="0 -0.0685 0.0315"
      rpy="1.5708 0 0" />
    <parent
      link="Link1" />
    <child
      link="Link2" />
    <axis
      xyz="0 0 1" />
    <limit
      lower="-3.14"
      upper="3.14"
      effort="0"
      velocity="0" />
  </joint>
  <link
    name="Link3">
    <inertial>
      <origin
        xyz="0.3007517628030454 0.00021830025116623735 -0.017920118117320687"
        rpy="0 0 0" />
      <mass
        value="0.444800458017923"  />
      <inertia
        ixx="0.0008033142320190526"
        ixy="2.479628361292348e-05"
        ixz="0.0007740027206152985"
        iyy="0.006549830957859297"
        iyz="-8.928123671227523e-06"
        izz="0.005959780263342135" />
    </inertial>
    <visual>
      <origin
        xyz="0 0 0"
        rpy="0 0 0" />
      <geometry>
        <mesh
          filename="package://dynamics/src/dynamics/meshes/single_arm_v12_3_12.0.STL" />
      </geometry>
      <material
        name="">
        <color
          rgba="0.898039215686275 0.917647058823529 0.929411764705882 1" />
      </material>
    </visual>
    <collision>
      <origin
        xyz="0 0 0"
        rpy="0 0 0" />
      <geometry>
        <mesh
          filename="package://single_arm_v12/meshes/Link3.STL" />
      </geometry>
    </collision>
  </link>
  <joint
    name="Joint3"
    type="revolute">
    <origin
      xyz="0.2551977978922024 0 -0.0325"
      rpy="0 0 0" />
    <parent
      link="Link2" />
    <child
      link="Link3" />
    <axis
      xyz="0 0 -1" />
    <limit
      lower="-3.14"
      upper="3.14"
      effort="0"
      velocity="0" />
  </joint>
  <link
    name="Link4">
    <inertial>
      <origin
        xyz="-1.11022302462516E-16 0.0124471610012716 0.0305494763505743"
        rpy="0 0 0" />
      <mass
        value="0.313854171959486" />
      <inertia
        ixx="0.00030905374217572"
        ixy="2.20104937481116E-19"
        ixz="1.99389141092033E-20"
        iyy="0.000138417182248756"
        iyz="-3.51429818496687E-06"
        izz="0.000324741574348905" />
    </inertial>
    <visual>
      <origin
        xyz="0 0 0"
        rpy="0 0 0" />
      <geometry>
        <mesh
          filename="package://single_arm_v12/meshes/Link4.STL" />
      </geometry>
      <material
        name="">
        <color
          rgba="0.898039215686275 0.917647058823529 0.929411764705882 1" />
      </material>
    </visual>
    <collision>
      <origin
        xyz="0 0 0"
        rpy="0 0 0" />
      <geometry>
        <mesh
          filename="package://single_arm_v12/meshes/Link4.STL" />
      </geometry>
    </collision>
  </link>
  <joint
    name="Joint4"
    type="revolute">
    <origin
      xyz="0.3935003246501293 0 0.0325"
      rpy="0 0 3.1416" />
    <parent
      link="Link3" />
    <child
      link="Link4" />
    <axis
      xyz="0 0 1" />
    <limit
      lower="-3.14"
      upper="3.14"
      effort="0"
      velocity="0" />
  </joint>
  <link
    name="Link5">
    <inertial>
      <origin
        xyz="0.0305494763505902 0.0124160882702156 -0.000878959076247798"
        rpy="0 0 0" />
      <mass
        value="0.313854171959487" />
      <inertia
        ixx="0.000324741574348905"
        ixy="-3.50552519309465E-06"
        ixz="2.48162957481373E-07"
        iyy="0.000139268063164469"
        iyz="1.20194589741801E-05"
        izz="0.000308202861260008" />
    </inertial>
    <visual>
      <origin
        xyz="0 0 0"
        rpy="0 0 0" />
      <geometry>
        <mesh
          filename="package://single_arm_v12/meshes/Link5.STL" />
      </geometry>
      <material
        name="">
        <color
          rgba="0.898039215686275 0.917647058823529 0.929411764705882 1" />
      </material>
    </visual>
    <collision>
      <origin
        xyz="0 0 0"
        rpy="0 0 0" />
      <geometry>
        <mesh
          filename="package://single_arm_v12/meshes/Link5.STL" />
      </geometry>
    </collision>
  </link>
  <joint
    name="Joint5"
    type="revolute">
    <origin
      xyz="0 0.0685 0.0346"
      rpy="1.5708 0 1.5708" />
    <parent
      link="Link4" />
    <child
      link="Link5" />
    <axis
      xyz="-1 0 0" />
    <limit
      lower="-3.14"
      upper="3.14"
      effort="0"
      velocity="0" />
  </joint>
  <link
    name="Link6">
    <inertial>
      <origin
        xyz="-0.20184 0.067993 -0.13565"
        rpy="0 0 0" />
      <mass
        value="5.5581" />
      <inertia
        ixx="0.039288"
        ixy="-0.0053509"
        ixz="-0.046451"
        iyy="0.22224"
        iyz="-5.0688E-05"
        izz="0.21337" />
    </inertial>
    <visual>
      <origin
        xyz="0 0 0"
        rpy="0 0 0" />
      <geometry>
        <mesh
          filename="package://single_arm_v12/meshes/Link6.STL" />
      </geometry>
      <material
        name="">
        <color
          rgba="1 1 1 1" />
      </material>
    </visual>
    <collision>
      <origin
        xyz="0 0 0"
        rpy="0 0 0" />
      <geometry>
        <mesh
          filename="package://single_arm_v12/meshes/Link6.STL" />
      </geometry>
    </collision>
  </link>
  <joint
    name="Joint6"
    type="revolute">
    <origin
      xyz="0.0346 0.068329 -0.0048371"
      rpy="3.1416 1.5001 -1.5708" />
    <parent
      link="Link5" />
    <child
      link="Link6" />
    <axis
      xyz="0 0 1" />
    <limit
      lower="-3.14"
      upper="3.14"
      effort="0"
      velocity="0" />
  </joint>
</robot>