<?xml version="1.0" encoding="utf-8"?>
<robot
    name="single_arm">
    <link name="dummy"/>
    <joint name="dummy_joint" type="fixed">
        <parent link="dummy"/>
        <child link="l_Base"/>
        </joint>
        <link
            name="l_Base">
            <inertial>
            <origin
            xyz="0.000156250860732315 0.000202963757501797 -0.0546720420122521"
            rpy="0 0 0" />
            <mass
            value="0.323603974032196" />
            <inertia ixx="0.1" ixy="0.0"  ixz="0.0"  
            iyy="0.1" iyz="0.0"
            izz="0.1" />
            </inertial>
            <visual>
            <origin
            xyz="0 0 0"
            rpy="0 0 0" />
            <geometry>
            <mesh
            filename="package://single_arm_description/meshes/Base.STL" />
            </geometry>
            <material
            name="">
            <color
            rgba="0.792156862745098 0.819607843137255 0.933333333333333 1" />
            </material>
            </visual>
            <collision>
            <origin
            xyz="0 0 0"
            rpy="0 0 0" />
            <geometry>
            <mesh
            filename="package://single_arm_description/meshes/Base.STL" />
            </geometry>
            </collision>
        </link>


        <link
            name="l_Link_1">
            <inertial>
            <origin
            xyz="-3.64540734812575E-06 0.00119778550610652 -0.000421399675048756"
            rpy="0 0 0" />
            <mass
            value="0.386131223153925" />
            <inertia ixx="0.1" ixy="0.0"  ixz="0.0"  
            iyy="0.1" iyz="0.0"
            izz="0.1" />
            </inertial>
            <visual>
            <origin
            xyz="0 0 0"
            rpy="0 0 0" />
            <geometry>
            <mesh
            filename="package://single_arm_description/meshes/Link_1.STL" />
            </geometry>
            <material
            name="">
            <color
            rgba="0.898039215686275 0.917647058823529 0.929411764705882 1" />
            </material>
            </visual>
            <collision>
            <origin
            xyz="0 0 0"
            rpy="0 0 0" />
            <geometry>
            <mesh
            filename="package://single_arm_description/meshes/Link_1.STL" />
            </geometry>
            </collision>
        </link>
        <joint
            name="l_joint_1"
            type="revolute">
            <origin
            xyz="0 0 0.0550000000000002"
            rpy="-1.5707963267949 -2.60398896659329E-32 1.5707963267949" />
            <parent
            link="l_Base" />
            <child
            link="l_Link_1" />
            <axis
            xyz="0 -1 0" />
            <limit
            lower="-3.14"
            upper="3.14"
            effort="1000"
            velocity="6.5" />
            <dynamics damping="0.7"/>
        </joint>
        <link
            name="l_Link_2">
            <inertial>
            <origin
            xyz="0.000683310419598862 -8.00535195483731E-05 0.117541995924546"
            rpy="0 0 0" />
            <mass
            value="0.479430893999342" />
            <inertia ixx="0.1" ixy="0.0"  ixz="0.0"  
            iyy="0.1" iyz="0.0"
            izz="0.1" />
            </inertial>
            <visual>
            <origin
            xyz="0 0 0"
            rpy="0 0 0" />
            <geometry>
            <mesh
            filename="package://single_arm_description/meshes/Link_2.STL" />
            </geometry>
            <material
            name="">
            <color
            rgba="0.898039215686275 0.917647058823529 0.929411764705882 1" />
            </material>
            </visual>
            <collision>
            <origin
            xyz="0 0 0"
            rpy="0 0 0" />
            <geometry>
            <mesh
            filename="package://single_arm_description/meshes/Link_2.STL" />
            </geometry>
            </collision>
        </link>
        <joint
            name="l_joint_2"
            type="revolute">
            <origin
            xyz="0 0 0"
            rpy="-1.5707963267949 7.39557098644699E-32 -1.5707963267949" />
            <parent
            link="l_Link_1" />
            <child
            link="l_Link_2" />
            <axis
            xyz="0 -1 0" />
            <limit
            lower="-3.14"
            upper="3.14"
            effort="1000"
            velocity="6.5" />
            <dynamics damping="0.7"/>
        </joint>
        <link
            name="l_Link_3">
            <inertial>
            <origin
            xyz="-0.0220564838621471 0.101455973505417 -8.62457453022769E-05"
            rpy="0 0 0" />
            <mass
            value="0.568306813792926" />
            <inertia ixx="0.1" ixy="0.0"  ixz="0.0"  
            iyy="0.1" iyz="0.0"
            izz="0.1" />
            </inertial>
            <visual>
            <origin
            xyz="0 0 0"
            rpy="0 0 0" />
            <geometry>
            <mesh
            filename="package://single_arm_description/meshes/Link_3.STL" />
            </geometry>
            <material
            name="">
            <color
            rgba="0.898039215686275 0.917647058823529 0.929411764705882 1" />
            </material>
            </visual>
            <collision>
            <origin
            xyz="0 0 0"
            rpy="0 0 0" />
            <geometry>
            <mesh
            filename="package://single_arm_description/meshes/Link_3.STL" />
            </geometry>
            </collision>
        </link>
        <joint
            name="l_joint_3"
            type="revolute">
            <origin
            xyz="0 0 0.174"
            rpy="1.5707963267949 4.63843178081015E-17 6.91111242388425E-16" />
            <parent
            link="l_Link_2" />
            <child
            link="l_Link_3" />
            <axis
            xyz="0 1 0" />
            <limit
            lower="-3.14"
            upper="3.14"
            effort="1000"
            velocity="6.5" />
            <dynamics damping="0.7"/>
        </joint>
        <link
            name="l_Link_4">
            <inertial>
            <origin
            xyz="0.0297389855299131 0.0361651889050357 0.108377256276242"
            rpy="0 0 0" />
            <mass
            value="0.457613402476782" />
            <inertia ixx="0.1" ixy="0.0"  ixz="0.0"  
            iyy="0.1" iyz="0.0"
            izz="0.1" />
            </inertial>
            <visual>
            <origin
            xyz="0 0 0"
            rpy="0 0 0" />
            <geometry>
            <mesh
            filename="package://single_arm_description/meshes/Link_4.STL" />
            </geometry>
            <material
            name="">
            <color
            rgba="0.898039215686275 0.917647058823529 0.929411764705882 1" />
            </material>
            </visual>
            <collision>
            <origin
            xyz="0 0 0"
            rpy="0 0 0" />
            <geometry>
            <mesh
            filename="package://single_arm_description/meshes/Link_4.STL" />
            </geometry>
            </collision>
        </link>
        <joint
            name="l_joint_4"
            type="revolute">
            <origin
            xyz="-0.0299999998727122 0.115999993001519 0.0359999999999999"
            rpy="-1.5707963267949 -1.40443212615082E-14 1.75438367537121E-15" />
            <parent
            link="l_Link_3" />
            <child
            link="l_Link_4" />
            <axis
            xyz="0 -1 0" />
            <limit
            lower="-3.14"
            upper="3.14"
            effort="1000"
            velocity="6.5" />
            <dynamics damping="0.7"/>
        </joint>
        <link
            name="l_Link_5">
            <inertial>
            <origin
            xyz="-0.000172095429412281 0.102690028206534 -6.66794215013755E-05"
            rpy="0 0 0" />
            <mass
            value="0.448277275798768" />
            <inertia ixx="0.1" ixy="0.0"  ixz="0.0"  
            iyy="0.1" iyz="0.0"
            izz="0.1" />
            </inertial>
            <visual>
            <origin
            xyz="0 0 0"
            rpy="0 0 0" />
            <geometry>
            <mesh
            filename="package://single_arm_description/meshes/Link_5.STL" />
            </geometry>
            <material
            name="">
            <color
            rgba="0.792156862745098 0.819607843137255 0.933333333333333 1" />
            </material>
            </visual>
            <collision>
            <origin
            xyz="0 0 0"
            rpy="0 0 0" />
            <geometry>
            <mesh
            filename="package://single_arm_description/meshes/Link_5.STL" />
            </geometry>
            </collision>
        </link>
        <joint
            name="l_joint_5"
            type="revolute">
            <origin
            xyz="0.029999999872713 0.0359999999999987 0.162"
            rpy="1.5707963267949 -8.80083043478898E-16 -2.49800180540655E-16" />
            <parent
            link="l_Link_4" />
            <child
            link="l_Link_5" />
            <axis
            xyz="0 1 0" />
            <limit
            lower="-3.14"
            upper="3.14"
            effort="1000"
            velocity="6.5" />
            <dynamics damping="0.7"/>
        </joint>
        <link
            name="l_Link_6">
            <inertial>
            <origin
            xyz="1.14707347786958E-08 0.0359051244401507 0.076720238383497"
            rpy="0 0 0" />
            <mass
            value="0.205818407044008" />
            <inertia ixx="0.1" ixy="0.0"  ixz="0.0"  
            iyy="0.1" iyz="0.0"
            izz="0.1" />
            </inertial>
            <visual>
            <origin
            xyz="0 0 0"
            rpy="0 0 0" />
            <geometry>
            <mesh
            filename="package://single_arm_description/meshes/Link_6.STL" />
            </geometry>
            <material
            name="">
            <color
            rgba="0.898039215686275 0.917647058823529 0.929411764705882 1" />
            </material>
            </visual>
            <collision>
            <origin
            xyz="0 0 0"
            rpy="0 0 0" />
            <geometry>
            <mesh
            filename="package://single_arm_description/meshes/Link_6.STL" />
            </geometry>
            </collision>
        </link>
        <joint
            name="l_joint_6"
            type="revolute">
            <origin
            xyz="0 0.108000511190835 0.0360000000000014"
            rpy="-1.5707963267949 0 4.46815747097797E-32" />
            <parent
            link="l_Link_5" />
            <child
            link="l_Link_6" />
            <axis
            xyz="0 -1 0" />
            <limit
            lower="-3.14"
            upper="3.14"
            effort="1000"
            velocity="6.5" />
            <dynamics damping="0.7"/>
        </joint>
        <!-- <link
            name="tool">
            <inertial>
            <origin
                xyz="-4.4856E-13 0 0.025"
                rpy="0 0 0" />
            <mass
                value="0.3927" />
            <inertia
                ixx="0.00032725"
                ixy="1.2071E-31"
                ixz="-2.9355E-15"
                iyy="0.00032725"
                iyz="1.09E-19"
                izz="0.00049087" />
            </inertial>
            <visual>
            <origin
                xyz="0 0 0"
                rpy="0 0 0" />
            <geometry>
                <mesh
                filename="package:/single_arm_description/meshes/tool.STL" />
            </geometry>
            <material
                name="">
                <color
                rgba="0.79216 0.81961 0.93333 1" />
            </material>
            </visual>
            <collision>
            <origin
                xyz="0 0 0"
                rpy="0 0 0" />
            <geometry>
                <mesh
                filename="package:/single_arm_description/meshes/tool.STL" />
            </geometry>
            </collision>
        </link>
		<joint
			name="l_joint_7"
			type="revolute">
			<origin
				xyz="0 0.03680 0.135"
                rpy="0 0 1.57" />

			<parent
				link="l_Link_6" />
			<child
				link="tool" />
			<axis 
				xyz="0 0 1" />
			<limit
				lower="-6.28"
				upper="6.28"
				effort="300"
                velocity="1.0" />
		</joint> -->
</robot>
